<?xml version='1.0'?>

<robot name="trixy" xmlns:xacro="http://www.ros.org/wiki/xacro">

  <xacro:include filename="$(find trixy)/urdf/trixy.gazebo" />
  
  <gazebo reference="left_wheel">
    <material>Gazebo/Green</material>
  </gazebo>

  <gazebo reference="right_wheel">
    <material>Gazebo/Green</material>
  </gazebo>
  
  <gazebo reference="rfid_holder">
    <material>Gazebo/Blue</material>
  </gazebo>
  
  <gazebo reference="rfid_slider_support">
    <material>Gazebo/Green</material>
  </gazebo>

  

  <gazebo reference="chassis">
    <material>Gazebo/Blue</material>
  </gazebo>
  <link name="robot_footprint"></link>
  

  <joint name="robot_footprint_joint" type="fixed">
    <origin xyz="0 0 0" rpy="0 0 0" />
    <parent link="robot_footprint"/>
    <child link="chassis" />
  </joint>
  
  <joint name="rfid_slider_support_joint" type="fixed">
    <origin xyz ="0 0 0" rpy="0 0 0"/>
    <parent link="robot_footprint"/>
    <child link="rfid_slider_support"/>
  </joint>
  
  
  
  <joint name="rfid_slider" type="prismatic">
  <origin xyz="0.0 0.0 0.0" rpy="0 0 0"/>
  <parent link="robot_footprint"/>
  <child link="rfid_holder"/>
    <axis xyz="0.0 0.0 1.0"/>
    <limit upper="1.0" lower="0.24" effort="100" velocity="100"/>
  </joint>


  
  

  <joint type="continuous" name="left_wheel_hinge">
    <origin xyz="0 0.30 0" rpy="0 0 0" />
    <parent link="chassis"/>
    <child link="left_wheel" />
    <axis xyz="0 1 0" rpy="0 0 0" />
    <limit effort="10000" velocity="1000" />
    <dynamics damping="1.0" friction="1.0" />
  </joint>

  <joint type="continuous" name="right_wheel_hinge">
    <origin xyz="0 -0.30 0" rpy="0 0 0" />
    <parent link="chassis"/>
    <child link="right_wheel" />
    <axis xyz="0 1 0" rpy="0 0 0" />
    <limit effort="10000" velocity="1000" />
    <dynamics damping="1.0" friction="1.0" />
  </joint>
  
  


  

  <link name="left_wheel">
    <inertial>
      <mass value="5"/>
      <origin xyz="0 0 0" rpy="0 1.5707 1.5707"/>
      <inertia
        ixx="0.1" ixy="0.0" ixz="0.0"
        iyy="0.1" iyz="0.0"
        izz="0.1"
      />
    </inertial>

    <collision>
      <origin xyz="0 0 0" rpy="0 1.5707 1.5707"/>
      <geometry>
        <cylinder radius="0.1" length="0.05"/>
      </geometry>
    </collision>

    <visual>
      <origin xyz="0 0 0" rpy="0 1.5707 1.5707"/>
      <geometry>
        <cylinder radius="0.1" length="0.05"/>
      </geometry>
    </visual>

  </link>

  <link name="right_wheel">
    <inertial>
      <mass value="5"/>
      <origin xyz="0 0 0" rpy="0 1.5707 1.5707"/>
      <inertia
        ixx="0.1" ixy="0.0" ixz="0.0"
        iyy="0.1" iyz="0.0"
        izz="0.1"
      />
    </inertial>

    <collision>
      <origin xyz="0 0 0" rpy="0 1.5707 1.5707"/>
      <geometry>
        <cylinder radius="0.1" length="0.05"/>
      </geometry>
    </collision>

    <visual>
      <origin xyz="0 0 0" rpy="0 1.5707 1.5707"/>
      <geometry>
        <cylinder radius="0.1" length="0.05"/>
      </geometry>
    </visual>

  </link>
  
 <link name='rfid_holder'>
   <inertial>
     <origin xyz="0.012285263888850092 -8.326672684688674e-17 0.20264251775704167" rpy="0 0 0"/>
     <mass value="1.4196602693651297"/>
     <inertia ixx="0.009879" iyy="0.009869" izz="0.000863" ixy="0.0" iyz="-0.0" ixz="-0.001412"/>
    </inertial>
    <visual>
     <origin xyz="0.1 0.1 -0.05" rpy="0 0 0.0"/>
     <geometry>
       <mesh filename="package://trixy/meshes/rfid_holder_2.stl" scale="0.001 0.001 0.001"/>
     </geometry>
   </visual>
   <collision>
      <origin xyz="0.1 0.1 -0.05" rpy="0 0 0.0"/>
      <geometry>
       <mesh filename="package://trixy/meshes/rfid_holder_2.stl" scale="0.001 0.001 0.001"/>
      </geometry>
    </collision>
  </link>
  
  <link name='rfid_slider_support'>
  <inertial>
     <origin xyz="0.012285263888850092 -8.326672684688674e-17 0.20264251775704167" rpy="0 0 0"/>
     <mass value="1.4196602693651297"/>
     <inertia ixx="0.009879" iyy="0.009869" izz="0.000863" ixy="0.0" iyz="-0.0" ixz="-0.001412"/>
    </inertial>
    
      <visual>
      <origin xyz="0.1 0.1 0" rpy="0 0 0"/>
      <geometry>
        <mesh filename="package://trixy/meshes/rfid_slider_support_1.stl" scale="0.001 0.001 0.001"/>
      </geometry>
    </visual>
    
    <collision>
      <origin xyz="0.1 0.1 0.0" rpy="0 0 0"/>
      <geometry>
       <mesh filename="package://trixy/meshes/rfid_slider_support_1.stl" scale="0.001 0.001 0.001"/>
      </geometry>
    </collision>
    
    </link>
    
    

  <link name='chassis'>
    <pose>1.34 3.78 0.35 0 0 0</pose>

    <inertial>
      <mass value="15.0"/>
      <origin xyz="0.0 0 0" rpy=" 0 0 0"/>
      <inertia
          ixx="0.1" ixy="0" ixz="0"
          iyy="0.1" iyz="0"
          izz="0.1"
      />
    </inertial>

    <collision name='collision'>
      <origin xyz="0 0 0.05" rpy=" 0 0 0"/> 
      <geometry>
        <cylinder length="0.2" radius="0.25"/>
      </geometry>
    </collision>

    <visual name='chassis_visual'>
      <origin xyz="0 0 0.05" rpy=" 0 0 0"/>
      <geometry>
       <cylinder length="0.2" radius="0.25"/>
      </geometry>
    </visual>


    <collision name='back_caster_collision'>
      <origin xyz="-0.15 0 -0.05" rpy=" 0 0 0"/>
      <geometry>
        <sphere radius="0.0499"/>
      </geometry>
    </collision>

    <visual name='back_caster_visual'>
      <origin xyz="-0.15 0 -0.05" rpy=" 0 0 0"/>
      <geometry>
        <sphere radius="0.05"/>
      </geometry>
    </visual>

    <collision name='front_caster_collision'>
      <origin xyz="0.15 0 -0.05" rpy=" 0 0 0"/>
      <geometry>
        <sphere radius="0.0499"/>
      </geometry>
    </collision>

    <visual name='front_caster_visual'>
      <origin xyz="0.15 0 -0.05" rpy=" 0 0 0"/>
      <geometry>
        <sphere radius="0.05"/>
      </geometry>
    </visual>

  </link>

</robot>
